<?xml version="1.0"?> 
<sdf version="1.7">
  <world name="trial_1_world">

    <gui>
      <camera name="user_camera">
        <pose>0 -15 4 0 0.3 1.57</pose>
      </camera>
    </gui>

    <scene>
      <sky>
        <clouds>
          <speed>12</speed>
        </clouds>
      </sky>
    </scene>

    <model name='rover'>
      <pose>0 -6 0 0 0 1.57</pose>

      <link name='chassis'>
        <inertial>
            <mass>0.2</mass>
            <inertia>
              <ixx>0.01</ixx>
              <iyy>0.01</iyy>
              <izz>0.01</izz>
            </inertia>
          </inertial>

        <visual name='chassis_visual'>
            <pose>0 0 0 0 0 0</pose>
            <geometry>
              <box>
                <size>0.2 0.1 0.03</size>
              </box>
            </geometry>
            <material>
              <script>
                <uri>file://media/materials/scripts/gazebo.material</uri>
                <name>Gazebo/DarkGrey</name>
              </script>
            </material>
          </visual>

          <collision name='chassis_collision'>
            <pose>0 0 0 0 0 0</pose>
            <geometry>
              <box>
                <size>0.2 0.1 0.03</size>
              </box>
            </geometry>
          </collision>

        <visual name='computer_visual'>
            <pose>-0.05 0 0.03 0 0 0</pose>
            <geometry>
              <box>
                <size>0.1 0.07 0.01</size>
              </box>
            </geometry>
            <material>
              <script>
                <uri>file://media/materials/scripts/gazebo.material</uri>
                <name>Gazebo/Green</name>
              </script>
            </material>
          </visual>

          <collision name='computer_collision'>
            <pose>-0.05 0 0.03 0 0 0</pose>
            <geometry>
              <box>
                <size>0.1 0.07 0.01</size>
              </box>
            </geometry>
          </collision>

      </link>
      <link name="front_left">
        <pose>0.08 0.07 -0.01 -1.5707 0 0</pose>
        <inertial>
            <mass>0.005</mass>
            <inertia>
              <ixx>0.0001</ixx>
              <iyy>0.0001</iyy>
              <izz>0.0001</izz>
            </inertia>
          </inertial>

        <collision name="collision">
          <geometry>
            <cylinder>
              <radius>0.03</radius>
              <length>0.02</length>
            </cylinder>
          </geometry>
        </collision>

        <visual name="tire">
          <geometry>
            <cylinder>
              <radius>0.03</radius>
              <length>0.02</length>
            </cylinder>
          </geometry>
          <material>
            <script>
              <uri>file://media/materials/scripts/gazebo.material</uri>
              <name>Gazebo/DarkGrey</name>
            </script>
          </material>
        </visual>

        <visual name="wheel">
          <geometry>
            <cylinder>
              <radius>0.028499999999999998</radius>
              <length>0.022</length>
            </cylinder>
          </geometry>
          <material>
            <script>
              <uri>file://media/materials/scripts/gazebo.material</uri>
              <name>Gazebo/Yellow</name>
            </script>
          </material>
        </visual>

        <visual name="wheel_line">
          <geometry>
            <box>
              <size>0.053 0.01 0.024</size>
            </box>
          </geometry>
          <material>
            <script>
              <uri>file://media/materials/scripts/gazebo.material</uri>
              <name>Gazebo/DarkGrey</name>
            </script>
          </material>
        </visual>

        <visual name="wheel_line2">
          <geometry>
            <box>
              <size>0.01 0.053 0.024</size>
            </box>
          </geometry>
          <material>
            <script>
              <uri>file://media/materials/scripts/gazebo.material</uri>
              <name>Gazebo/DarkGrey</name>
            </script>
          </material>
        </visual>

      </link>

      <joint type="revolute" name="front_left_joint">
        <child>front_left</child>
        <parent>chassis</parent>
        <axis>
          <xyz>0 0 1</xyz>
          <dynamics>
            <friction>0.01</friction>
            <damping>0.01</damping>
          </dynamics>
        </axis>
      </joint>
      
      <link name="front_right">
        <pose>0.08 -0.07 -0.01 -1.5707 0 0</pose>
        <inertial>
            <mass>0.005</mass>
            <inertia>
              <ixx>0.0001</ixx>
              <iyy>0.0001</iyy>
              <izz>0.0001</izz>
            </inertia>
          </inertial>

        <collision name="collision">
          <geometry>
            <cylinder>
              <radius>0.03</radius>
              <length>0.02</length>
            </cylinder>
          </geometry>
        </collision>

        <visual name="tire">
          <geometry>
            <cylinder>
              <radius>0.03</radius>
              <length>0.02</length>
            </cylinder>
          </geometry>
          <material>
            <script>
              <uri>file://media/materials/scripts/gazebo.material</uri>
              <name>Gazebo/DarkGrey</name>
            </script>
          </material>
        </visual>

        <visual name="wheel">
          <geometry>
            <cylinder>
              <radius>0.028499999999999998</radius>
              <length>0.022</length>
            </cylinder>
          </geometry>
          <material>
            <script>
              <uri>file://media/materials/scripts/gazebo.material</uri>
              <name>Gazebo/Yellow</name>
            </script>
          </material>
        </visual>

        <visual name="wheel_line">
          <geometry>
            <box>
              <size>0.053 0.01 0.024</size>
            </box>
          </geometry>
          <material>
            <script>
              <uri>file://media/materials/scripts/gazebo.material</uri>
              <name>Gazebo/DarkGrey</name>
            </script>
          </material>
        </visual>

        <visual name="wheel_line2">
          <geometry>
            <box>
              <size>0.01 0.053 0.024</size>
            </box>
          </geometry>
          <material>
            <script>
              <uri>file://media/materials/scripts/gazebo.material</uri>
              <name>Gazebo/DarkGrey</name>
            </script>
          </material>
        </visual>

      </link>

      <joint type="revolute" name="front_right_joint">
        <child>front_right</child>
        <parent>chassis</parent>
        <axis>
          <xyz>0 0 1</xyz>
          <dynamics>
            <friction>0.01</friction>
            <damping>0.01</damping>
          </dynamics>
        </axis>
      </joint>
      
      <link name="rear_left">
        <pose>-0.08 0.07 -0.01 -1.5707 0 0</pose>
        <inertial>
            <mass>0.005</mass>
            <inertia>
              <ixx>0.0001</ixx>
              <iyy>0.0001</iyy>
              <izz>0.0001</izz>
            </inertia>
          </inertial>

        <collision name="collision">
          <geometry>
            <cylinder>
              <radius>0.03</radius>
              <length>0.02</length>
            </cylinder>
          </geometry>
        </collision>

        <visual name="tire">
          <geometry>
            <cylinder>
              <radius>0.03</radius>
              <length>0.02</length>
            </cylinder>
          </geometry>
          <material>
            <script>
              <uri>file://media/materials/scripts/gazebo.material</uri>
              <name>Gazebo/DarkGrey</name>
            </script>
          </material>
        </visual>

        <visual name="wheel">
          <geometry>
            <cylinder>
              <radius>0.028499999999999998</radius>
              <length>0.022</length>
            </cylinder>
          </geometry>
          <material>
            <script>
              <uri>file://media/materials/scripts/gazebo.material</uri>
              <name>Gazebo/Yellow</name>
            </script>
          </material>
        </visual>

        <visual name="wheel_line">
          <geometry>
            <box>
              <size>0.053 0.01 0.024</size>
            </box>
          </geometry>
          <material>
            <script>
              <uri>file://media/materials/scripts/gazebo.material</uri>
              <name>Gazebo/DarkGrey</name>
            </script>
          </material>
        </visual>

        <visual name="wheel_line2">
          <geometry>
            <box>
              <size>0.01 0.053 0.024</size>
            </box>
          </geometry>
          <material>
            <script>
              <uri>file://media/materials/scripts/gazebo.material</uri>
              <name>Gazebo/DarkGrey</name>
            </script>
          </material>
        </visual>

      </link>

      <joint type="revolute" name="rear_left_joint">
        <child>rear_left</child>
        <parent>chassis</parent>
        <axis>
          <xyz>0 0 1</xyz>
          <dynamics>
            <friction>0.01</friction>
            <damping>0.01</damping>
          </dynamics>
        </axis>
      </joint>
      
      <link name="rear_right">
        <pose>-0.08 -0.07 -0.01 -1.5707 0 0</pose>
        <inertial>
            <mass>0.005</mass>
            <inertia>
              <ixx>0.0001</ixx>
              <iyy>0.0001</iyy>
              <izz>0.0001</izz>
            </inertia>
          </inertial>

        <collision name="collision">
          <geometry>
            <cylinder>
              <radius>0.03</radius>
              <length>0.02</length>
            </cylinder>
          </geometry>
        </collision>

        <visual name="tire">
          <geometry>
            <cylinder>
              <radius>0.03</radius>
              <length>0.02</length>
            </cylinder>
          </geometry>
          <material>
            <script>
              <uri>file://media/materials/scripts/gazebo.material</uri>
              <name>Gazebo/DarkGrey</name>
            </script>
          </material>
        </visual>

        <visual name="wheel">
          <geometry>
            <cylinder>
              <radius>0.028499999999999998</radius>
              <length>0.022</length>
            </cylinder>
          </geometry>
          <material>
            <script>
              <uri>file://media/materials/scripts/gazebo.material</uri>
              <name>Gazebo/Yellow</name>
            </script>
          </material>
        </visual>

        <visual name="wheel_line">
          <geometry>
            <box>
              <size>0.053 0.01 0.024</size>
            </box>
          </geometry>
          <material>
            <script>
              <uri>file://media/materials/scripts/gazebo.material</uri>
              <name>Gazebo/DarkGrey</name>
            </script>
          </material>
        </visual>

        <visual name="wheel_line2">
          <geometry>
            <box>
              <size>0.01 0.053 0.024</size>
            </box>
          </geometry>
          <material>
            <script>
              <uri>file://media/materials/scripts/gazebo.material</uri>
              <name>Gazebo/DarkGrey</name>
            </script>
          </material>
        </visual>

      </link>

      <joint type="revolute" name="rear_right_joint">
        <child>rear_right</child>
        <parent>chassis</parent>
        <axis>
          <xyz>0 0 1</xyz>
          <dynamics>
            <friction>0.01</friction>
            <damping>0.01</damping>
          </dynamics>
        </axis>
      </joint>
      

      
      <include>
        <uri>model://red_ball</uri>
      </include>

      <joint name="red_ball_joint" type="fixed">
        <pose>-0.04 0 0.02 0 0 0</pose>
        <child>red_ball::link</child>
        <parent>chassis</parent>
      </joint>
      

      <plugin name="skid_steer_drive_controller" filename="libgazebo_ros_skid_steer_drive.so">
        <robotNamespace>rover</robotNamespace>
        <updateRate>100.0</updateRate>
        <leftFrontJoint>front_left_joint</leftFrontJoint>
        <rightFrontJoint>front_right_joint</rightFrontJoint>
        <leftRearJoint>rear_left_joint</leftRearJoint>
        <rightRearJoint>rear_right_joint</rightRearJoint>
        <wheelSeparation>0.14</wheelSeparation>
        <wheelDiameter>0.06</wheelDiameter>
        <robotBaseFrame>rover_ground_truth</robotBaseFrame>
        <torque>0.3</torque>
        <broadcastTF>true</broadcastTF>
        <commandTopic>cmd_vel</commandTopic>
        <odometryTopic>rover_odom</odometryTopic>
        <odometryFrame>map</odometryFrame>
        <covariance_x>0.0001</covariance_x>
        <covariance_y>0.0001</covariance_y>
        <covariance_yaw>0.0001</covariance_yaw>
      </plugin>
    </model>

    <model name="drone">
      <pose>0 -8 0 0 0 1.57</pose>

      <link name="base_link">
        <inertial>
            <mass>1.5</mass>
            <inertia>
              <ixx>0.029125</ixx> <iyy>0.029125</iyy>
              <izz>0.055225</izz>
            </inertia>
          </inertial>

        <visual name="fuselage_visual">
          <geometry>
              <mesh>
                <uri>model://px4vision/meshes/px4vision.stl</uri>
              </mesh>
            </geometry>
            <material>
              <script>
                <name>Gazebo/DarkGrey</name>
                <uri>file://media/materials/scripts/gazebo.material</uri>
              </script>
            </material>
        </visual>

        <collision name="fuselage_collision">
          <geometry>
              <box>
                <size>0.25 0.25 0.13</size>
              </box>
            </geometry>
          <surface>
            <contact>
              <ode>
                <min_depth>1e-6</min_depth>
                <max_vel>0.01</max_vel>
                <kp>1e6</kp>
                <kd>1</kd>
              </ode>
            </contact>
            <friction>
              <ode/>
            </friction>
          </surface>
        </collision>

        <collision name="mast_collision">
          <pose>0.06 0 0.11 0 0 0</pose>
          <geometry>
              <cylinder>
                <radius>0.03</radius>
                <length>0.1</length>
              </cylinder>
            </geometry>
        </collision>

        <sensor name="depth_camera" type="depth">
          <pose>0.09 0 -0.01 0 0 0</pose>
          <update_rate>15</update_rate>
          <visulize>1</visulize>
          <camera>
            <horizontal_fov>1.02974</horizontal_fov>
            <image>
              <format>R8G8B8</format>
              <width>640</width>
              <height>480</height>
            </image>
            <clip>
              <near>0.1</near>
              <far>11</far>
            </clip>
          </camera>
          <plugin filename="libgazebo_ros_openni_kinect.so" name="camera_controller">
            <robotNamespace>drone</robotNamespace>
            <cameraName>camera</cameraName>
            <alwaysOn>true</alwaysOn>
            <pointCloudCutoff>0.2</pointCloudCutoff>
            <pointCloudCutoffMax>10</pointCloudCutoffMax>
            <imageTopicName>color/image_raw</imageTopicName>
            <cameraInfoTopicName>color/camera_info</cameraInfoTopicName>
            <depthImageTopicName>depth/image_raw</depthImageTopicName>
            <depthImageCameraInfoTopicName>depth/camera_info</depthImageCameraInfoTopicName>
            <pointCloudTopicName>depth/points</pointCloudTopicName>
            <frameName>camera_link</frameName>
            <distortion_k1>0.0</distortion_k1>
            <distortion_k2>0.0</distortion_k2>
            <distortion_k3>0.0</distortion_k3>
            <distortion_t1>0.0</distortion_t1>
            <distortion_t2>0.0</distortion_t2>
          </plugin>
        </sensor>

      </link>

      <!--Rotor 0 -->
      <link name="rotor_0">

        <pose>0.091 -0.108 0.032 0 0 0</pose>
        <inertial>
              <mass>0.005</mass>
              <inertia>
                <ixx>8.000416666666669e-06</ixx> <iyy>8.000416666666669e-06</iyy>
                <izz>1.6000000000000003e-05</izz>
              </inertia>
            </inertial>
        <visual name="rotor_0_visual">
          <geometry>
              <mesh>
                <uri>model://px4vision/meshes/prop_ccw.stl</uri>
              </mesh>
            </geometry>
            <material>
              <script>
                <name>Gazebo/Grey</name>
                <uri>file://media/materials/scripts/gazebo.material</uri>
              </script>
            </material>
        </visual>

        <collision name="rotor_0_collision">
          <geometry>
              <cylinder>
                <radius>0.08</radius>
                <length>0.001</length>
              </cylinder>
            </geometry>
        </collision>

      </link>

      <joint name="rotor_0_joint" type="revolute">
        <parent>base_link</parent>
        <child>rotor_0</child>
        <axis>
          <xyz>0 0 1</xyz>
          <limit>
            <lower>-1e+16</lower>
            <upper>1e+16</upper>
          </limit>
          <use_parent_model_frame>1</use_parent_model_frame>
        </axis>
      </joint>

      <plugin name='rotor_0_motor_model' filename='libgazebo_motor_model.so'>
        <robotNamespace/>
        <jointName>rotor_0_joint</jointName>
        <linkName>rotor_0</linkName>
        <turningDirection>ccw</turningDirection>
        <timeConstantUp>0.0125</timeConstantUp>
        <timeConstantDown>0.025</timeConstantDown>
        <maxRotVelocity>1100</maxRotVelocity>
        <motorConstant>5.84e-06</motorConstant>
        <momentConstant>0.06</momentConstant>
        <commandSubTopic>/gazebo/command/motor_speed</commandSubTopic>
        <motorNumber>0</motorNumber>
        <rotorDragCoefficient>0.000175</rotorDragCoefficient>
        <rollingMomentCoefficient>1e-06</rollingMomentCoefficient>
        <motorSpeedPubTopic>/motor_speed/0</motorSpeedPubTopic>
        <rotorVelocitySlowdownSim>10</rotorVelocitySlowdownSim>
      </plugin>

      

      <!--Rotor 1 -->
      <link name="rotor_1">

        <pose>-0.097 0.108 0.032 0 0 0</pose>
        <inertial>
              <mass>0.005</mass>
              <inertia>
                <ixx>8.000416666666669e-06</ixx> <iyy>8.000416666666669e-06</iyy>
                <izz>1.6000000000000003e-05</izz>
              </inertia>
            </inertial>
        <visual name="rotor_1_visual">
          <geometry>
              <mesh>
                <uri>model://px4vision/meshes/prop_ccw.stl</uri>
              </mesh>
            </geometry>
            <material>
              <script>
                <name>Gazebo/Grey</name>
                <uri>file://media/materials/scripts/gazebo.material</uri>
              </script>
            </material>
        </visual>

        <collision name="rotor_1_collision">
          <geometry>
              <cylinder>
                <radius>0.08</radius>
                <length>0.001</length>
              </cylinder>
            </geometry>
        </collision>

      </link>

      <joint name="rotor_1_joint" type="revolute">
        <parent>base_link</parent>
        <child>rotor_1</child>
        <axis>
          <xyz>0 0 1</xyz>
          <limit>
            <lower>-1e+16</lower>
            <upper>1e+16</upper>
          </limit>
          <use_parent_model_frame>1</use_parent_model_frame>
        </axis>
      </joint>

      <plugin name='rotor_1_motor_model' filename='libgazebo_motor_model.so'>
        <robotNamespace/>
        <jointName>rotor_1_joint</jointName>
        <linkName>rotor_1</linkName>
        <turningDirection>ccw</turningDirection>
        <timeConstantUp>0.0125</timeConstantUp>
        <timeConstantDown>0.025</timeConstantDown>
        <maxRotVelocity>1100</maxRotVelocity>
        <motorConstant>5.84e-06</motorConstant>
        <momentConstant>0.06</momentConstant>
        <commandSubTopic>/gazebo/command/motor_speed</commandSubTopic>
        <motorNumber>1</motorNumber>
        <rotorDragCoefficient>0.000175</rotorDragCoefficient>
        <rollingMomentCoefficient>1e-06</rollingMomentCoefficient>
        <motorSpeedPubTopic>/motor_speed/1</motorSpeedPubTopic>
        <rotorVelocitySlowdownSim>10</rotorVelocitySlowdownSim>
      </plugin>

      

      <!--Rotor 2 -->
      <link name="rotor_2">

        <pose>0.091 0.108 0.032 0 0 0</pose>
        <inertial>
              <mass>0.005</mass>
              <inertia>
                <ixx>8.000416666666669e-06</ixx> <iyy>8.000416666666669e-06</iyy>
                <izz>1.6000000000000003e-05</izz>
              </inertia>
            </inertial>
        <visual name="rotor_2_visual">
          <geometry>
              <mesh>
                <uri>model://px4vision/meshes/prop_cw.stl</uri>
              </mesh>
            </geometry>
            <material>
              <script>
                <name>Gazebo/Grey</name>
                <uri>file://media/materials/scripts/gazebo.material</uri>
              </script>
            </material>
        </visual>

        <collision name="rotor_2_collision">
          <geometry>
              <cylinder>
                <radius>0.08</radius>
                <length>0.001</length>
              </cylinder>
            </geometry>
        </collision>

      </link>

      <joint name="rotor_2_joint" type="revolute">
        <parent>base_link</parent>
        <child>rotor_2</child>
        <axis>
          <xyz>0 0 1</xyz>
          <limit>
            <lower>-1e+16</lower>
            <upper>1e+16</upper>
          </limit>
          <use_parent_model_frame>1</use_parent_model_frame>
        </axis>
      </joint>

      <plugin name='rotor_2_motor_model' filename='libgazebo_motor_model.so'>
        <robotNamespace/>
        <jointName>rotor_2_joint</jointName>
        <linkName>rotor_2</linkName>
        <turningDirection>cw</turningDirection>
        <timeConstantUp>0.0125</timeConstantUp>
        <timeConstantDown>0.025</timeConstantDown>
        <maxRotVelocity>1100</maxRotVelocity>
        <motorConstant>5.84e-06</motorConstant>
        <momentConstant>0.06</momentConstant>
        <commandSubTopic>/gazebo/command/motor_speed</commandSubTopic>
        <motorNumber>2</motorNumber>
        <rotorDragCoefficient>0.000175</rotorDragCoefficient>
        <rollingMomentCoefficient>1e-06</rollingMomentCoefficient>
        <motorSpeedPubTopic>/motor_speed/2</motorSpeedPubTopic>
        <rotorVelocitySlowdownSim>10</rotorVelocitySlowdownSim>
      </plugin>

      

      <!--Rotor 3 -->
      <link name="rotor_3">

        <pose>-0.097 -0.108 0.032 0 0 0</pose>
        <inertial>
              <mass>0.005</mass>
              <inertia>
                <ixx>8.000416666666669e-06</ixx> <iyy>8.000416666666669e-06</iyy>
                <izz>1.6000000000000003e-05</izz>
              </inertia>
            </inertial>
        <visual name="rotor_3_visual">
          <geometry>
              <mesh>
                <uri>model://px4vision/meshes/prop_cw.stl</uri>
              </mesh>
            </geometry>
            <material>
              <script>
                <name>Gazebo/Grey</name>
                <uri>file://media/materials/scripts/gazebo.material</uri>
              </script>
            </material>
        </visual>

        <collision name="rotor_3_collision">
          <geometry>
              <cylinder>
                <radius>0.08</radius>
                <length>0.001</length>
              </cylinder>
            </geometry>
        </collision>

      </link>

      <joint name="rotor_3_joint" type="revolute">
        <parent>base_link</parent>
        <child>rotor_3</child>
        <axis>
          <xyz>0 0 1</xyz>
          <limit>
            <lower>-1e+16</lower>
            <upper>1e+16</upper>
          </limit>
          <use_parent_model_frame>1</use_parent_model_frame>
        </axis>
      </joint>

      <plugin name='rotor_3_motor_model' filename='libgazebo_motor_model.so'>
        <robotNamespace/>
        <jointName>rotor_3_joint</jointName>
        <linkName>rotor_3</linkName>
        <turningDirection>cw</turningDirection>
        <timeConstantUp>0.0125</timeConstantUp>
        <timeConstantDown>0.025</timeConstantDown>
        <maxRotVelocity>1100</maxRotVelocity>
        <motorConstant>5.84e-06</motorConstant>
        <momentConstant>0.06</momentConstant>
        <commandSubTopic>/gazebo/command/motor_speed</commandSubTopic>
        <motorNumber>3</motorNumber>
        <rotorDragCoefficient>0.000175</rotorDragCoefficient>
        <rollingMomentCoefficient>1e-06</rollingMomentCoefficient>
        <motorSpeedPubTopic>/motor_speed/3</motorSpeedPubTopic>
        <rotorVelocitySlowdownSim>10</rotorVelocitySlowdownSim>
      </plugin>

      

      <plugin name='p3d' filename='libgazebo_ros_p3d.so'>
        <robotNamespace>drone</robotNamespace>
        <bodyName>base_link</bodyName>
        <topicName>qualisys/drone</topicName>
        <frameName>map</frameName>
        <xyzOffset>0 0 0</xyzOffset>
        <rpyOffset>0 0 0</rpyOffset>
      </plugin>

      <plugin name='magnetometer_plugin' filename='libgazebo_magnetometer_plugin.so'>
        <robotNamespace/>
        <pubRate>100</pubRate>
        <noiseDensity>0.0004</noiseDensity>
        <randomWalk>6.4e-06</randomWalk>
        <biasCorrelationTime>600</biasCorrelationTime>
        <magTopic>/mag</magTopic>
      </plugin>

      <plugin name='barometer_plugin' filename='libgazebo_barometer_plugin.so'>
        <robotNamespace/>
        <pubRate>50</pubRate>
        <baroTopic>/baro</baroTopic>
        <baroDriftPaPerSec>0</baroDriftPaPerSec>
      </plugin>

      <plugin name='rotors_gazebo_imu_plugin' filename='libgazebo_imu_plugin.so'>
        <robotNamespace/>
        <linkName>base_link</linkName>
        <imuTopic>/imu</imuTopic>
        <gyroscopeNoiseDensity>0.00018665</gyroscopeNoiseDensity>
        <gyroscopeRandomWalk>3.8785e-05</gyroscopeRandomWalk>
        <gyroscopeBiasCorrelationTime>1000.0</gyroscopeBiasCorrelationTime>
        <gyroscopeTurnOnBiasSigma>0.0087</gyroscopeTurnOnBiasSigma>
        <accelerometerNoiseDensity>0.00186</accelerometerNoiseDensity>
        <accelerometerRandomWalk>0.006</accelerometerRandomWalk>
        <accelerometerBiasCorrelationTime>300.0</accelerometerBiasCorrelationTime>
        <accelerometerTurnOnBiasSigma>0.196</accelerometerTurnOnBiasSigma>
      </plugin>

      <plugin name='mavlink_interface' filename='libgazebo_mavlink_interface.so'>
        <robotNamespace/>
        <imuSubTopic>/imu</imuSubTopic>
        <magSubTopic>/mag</magSubTopic>
        <baroSubTopic>/baro</baroSubTopic>
        <mavlink_addr>INADDR_ANY</mavlink_addr>
        <mavlink_tcp_port>4560</mavlink_tcp_port>
        <mavlink_udp_port>14560</mavlink_udp_port>
        <serialEnabled>0</serialEnabled>
        <serialDevice>/dev/ttyACM0</serialDevice>
        <baudRate>921600</baudRate>
        <qgc_addr>INADDR_ANY</qgc_addr>
        <qgc_udp_port>14550</qgc_udp_port>
        <sdk_addr>INADDR_ANY</sdk_addr>
        <sdk_udp_port>14540</sdk_udp_port>
        <hil_mode>0</hil_mode>
        <hil_state_level>0</hil_state_level>
        <send_vision_estimation>0</send_vision_estimation>
        <send_odometry>1</send_odometry>
        <enable_lockstep>1</enable_lockstep>
        <use_tcp>1</use_tcp>
        <motorSpeedCommandPubTopic>/gazebo/command/motor_speed</motorSpeedCommandPubTopic>
        <control_channels><channel name='rotor1'>
            <input_index>0</input_index>
            <input_offset>0</input_offset>
            <input_scaling>1000</input_scaling>
            <zero_position_disarmed>0</zero_position_disarmed>
            <zero_position_armed>100</zero_position_armed>
            <joint_control_type>velocity</joint_control_type>
          </channel>
          <channel name='rotor2'>
            <input_index>1</input_index>
            <input_offset>0</input_offset>
            <input_scaling>1000</input_scaling>
            <zero_position_disarmed>0</zero_position_disarmed>
            <zero_position_armed>100</zero_position_armed>
            <joint_control_type>velocity</joint_control_type>
          </channel>
          <channel name='rotor3'>
            <input_index>2</input_index>
            <input_offset>0</input_offset>
            <input_scaling>1000</input_scaling>
            <zero_position_disarmed>0</zero_position_disarmed>
            <zero_position_armed>100</zero_position_armed>
            <joint_control_type>velocity</joint_control_type>
          </channel>
          <channel name='rotor4'>
            <input_index>3</input_index>
            <input_offset>0</input_offset>
            <input_scaling>1000</input_scaling>
            <zero_position_disarmed>0</zero_position_disarmed>
            <zero_position_armed>100</zero_position_armed>
            <joint_control_type>velocity</joint_control_type>
          </channel>
          
        </control_channels>
      </plugin>

    </model>

    <include>
      <uri>model://sun</uri>
    </include>

    <include>
      <uri>model://hangar_floor</uri>
    </include>

    <include>
      <uri>model://sample_course_2</uri>
    </include>

    <include>
      <pose>-3 -9 0 0 0 2.0</pose>
      <uri>model://person_standing</uri>
    </include>

    <include>
      <pose>0 -1.5 0 0 0 1.57</pose>
      <uri>model://everblock_tunnel</uri>
    </include>

  </world>
</sdf>

<!-- vim: set et ft=xml fenc=utf-8 ff=unix sts=0 sw=2 ts=2 : -->